<?xml version="1.0" ?>
<robot name="robot">
    <!-- Определение материалов для визуализации -->
    <material name="white">
        <color rgba="1 1 1 1" /> <!-- Белый цвет -->
    </material>

    <material name="orange">
        <color rgba="1 0.3 0.1 1"/> <!-- Оранжевый цвет -->
    </material>

    <material name="blue">
        <color rgba="0.2 0.2 1 1"/> <!-- Синий цвет -->
    </material>

    <material name="black">
        <color rgba="0 0 0 1"/> <!-- Черный цвет -->
    </material>

    <material name="red">
        <color rgba="1 0 0 1"/> <!-- Красный цвет -->
    </material>

    <material name="light_brown">
        <color rgba="0.8 0.52 0.25 1"/> <!-- Светло-коричневый цвет -->
    </material>

    <!-- Описание базового звена -->
    <link name="base_link">
    </link>

    <!-- Определение фиктивного звена base_footprint -->
    <link name="base_footprint">
    </link>

    <!-- Фиксированное соединение между base_link и base_footprint -->
    <joint name="base_footprint_joint" type="fixed">
        <parent link="base_link"/>
        <child link="base_footprint"/>
        <origin xyz="0 0 -0.138" rpy="0 0 0"/> <!-- Смещение по оси Z -->
    </joint>

    <!-- Фиксированное соединение между base_link и шасси -->
    <joint name="chassis_joint" type="fixed">
        <parent link="base_link"/>
        <child link="chassis"/>
        <origin xyz="-0.335 0 -0.01"/> <!-- Смещение по осям X и Z -->
    </joint>

    <!-- Описание шасси -->
    <link name="chassis">
        <inertial>
            <origin xyz="0.2175 0 0.1675" rpy="0 0 0"/> <!-- Центр масс -->
            <mass value="1.0" /> <!-- Масса -->
            <inertia ixx="0.0215479" ixy="0.0" ixz="0.0"
                     iyy="0.0272431" iyz="0.0"
                     izz="0.0362329" /> <!-- Момент инерции -->
        </inertial>
        <visual>
            <origin xyz="0.2175 0 0.1675"/> <!-- Смещение для визуализации -->
            <geometry>
                <box size="0.435 0.355 0.335"/> <!-- Форма шасси -->
            </geometry>
            <material name="light_brown"/> <!-- Материал для визуализации -->
        </visual>
        <collision>
            <origin xyz="0.2175 0 0.1675"/> <!-- Смещение для столкновений -->
            <geometry>
                <box size="0.435 0.355 0.335"/> <!-- Геометрия для столкновений -->
            </geometry>
        </collision>
    </link>

    <!-- Настройки для симуляции шасси в Gazebo -->
    <gazebo reference="chassis">
        <material>Gazebo/Orange</material>
    </gazebo>

    <!-- Описание соединения для левого колеса -->
    <joint name="left_wheel_joint" type="continuous">
        <parent link="base_link"/>
        <child link="left_wheel"/>
        <origin xyz="0 0.2 0" rpy="-1.5708 0 0" /> <!-- Смещение и ориентация -->
        <axis xyz="0 0 1"/> <!-- Ось вращения -->
    </joint>

    <!-- Описание левого колеса -->
    <link name="left_wheel">
        <visual>
            <geometry>
                <cylinder radius="0.066" length="0.052"/> <!-- Геометрия для визуализации колеса в форме цилиндра -->
            </geometry>
            <material name="black"/> <!-- Материал для визуализации -->
        </visual>
        <collision>
            <geometry>
                <sphere radius="0.066"/> <!-- Геометрия для обнаружения столкновений, в данном случае сфера -->
            </geometry>
        </collision>
        <inertial>
            <origin xyz="0 0 0" rpy="0 0 0"/> <!-- Центр масс колеса -->
            <mass value="0.05" /> <!-- Масса колеса -->
            <inertia ixx="0.000042" ixy="0.0" ixz="0.0"
                     iyy="0.000042" iyz="0.0"
                     izz="0.000227" /> <!-- Моменты инерции -->
        </inertial>
    </link>

    <!-- Настройки для визуализации левого колеса в Gazebo -->
    <gazebo reference="left_wheel">
        <material>Gazebo/Black</material>
    </gazebo>

    <!-- Описание соединения для правого колеса -->
    <joint name="right_wheel_joint" type="continuous">
        <parent link="base_link"/>
        <child link="right_wheel"/>
        <origin xyz="0 -0.2 0" rpy="1.5708 0 0" /> <!-- Смещение и ориентация -->
        <axis xyz="0 0 -1"/> <!-- Ось вращения колеса -->
    </joint>

    <!-- Описание правого колеса -->
    <link name="right_wheel">
        <visual>
            <geometry>
                <cylinder radius="0.066" length="0.052"/> <!-- Геометрия колеса в форме цилиндра -->
            </geometry>
            <material name="black"/> <!-- Материал для визуализации -->
        </visual>
        <collision>
            <geometry>
                <sphere radius="0.066"/> <!-- Геометрия столкновений, сфера -->
            </geometry>
        </collision>
        <inertial>
            <origin xyz="0 0 0" rpy="0 0 0"/> <!-- Центр масс колеса -->
            <mass value="0.05" /> <!-- Масса колеса -->
            <inertia ixx="0.000042" ixy="0.0" ixz="0.0"
                     iyy="0.000042" iyz="0.0"
                     izz="0.000227" /> <!-- Моменты инерции -->
        </inertial>
    </link>

    <!-- Настройки для визуализации правого колеса в Gazebo -->
    <gazebo reference="right_wheel">
        <material>Gazebo/Black</material>
    </gazebo>

    <!-- Описание соединения для заднего левого колеса -->
    <joint name="back_left_wheel_joint" type="continuous">
        <parent link="base_link"/>
        <child link="back_left_wheel"/>
        <origin xyz="-0.235 0.2 0" rpy="1.5708 0 0" /> <!-- Смещение и ориентация -->
        <axis xyz="0 0 -1"/> <!-- Ось вращения колеса -->
    </joint>

    <!-- Описание заднего левого колеса -->
    <link name="back_left_wheel">
        <visual>
            <geometry>
                <cylinder radius="0.066" length="0.052"/> <!-- Геометрия колеса в форме цилиндра -->
            </geometry>
            <material name="black"/> <!-- Материал для визуализации -->
        </visual>
        <collision>
            <geometry>
                <sphere radius="0.066"/> <!-- Геометрия столкновений, сфера -->
            </geometry>
        </collision>
        <inertial>
            <origin xyz="0 0 0" rpy="0 0 0"/> <!-- Центр масс колеса -->
            <mass value="0.05" /> <!-- Масса колеса -->
            <inertia ixx="0.000042" ixy="0.0" ixz="0.0"
                     iyy="0.000042" iyz="0.0"
                     izz="0.000227" /> <!-- Моменты инерции -->
        </inertial>
    </link>

    <!-- Настройки для визуализации заднего левого колеса в Gazebo -->
    <gazebo reference="back_left_wheel">
        <material>Gazebo/Black</material>
    </gazebo>

    <!-- Описание соединения для заднего правого колеса -->
    <joint name="back_right_wheel_joint" type="continuous">
        <parent link="base_link"/>
        <child link="back_right_wheel"/>
        <origin xyz="-0.235 -0.2 0" rpy="-1.5708 0 0" /> <!-- Смещение и ориентация -->
        <axis xyz="0 0 1"/> <!-- Ось вращения колеса -->
    </joint>

    <!-- Описание заднего правого колеса -->
    <link name="back_right_wheel">
        <visual>
            <geometry>
                <cylinder radius="0.066" length="0.052"/> <!-- Геометрия колеса -->
            </geometry>
            <material name="black"/> <!-- Материал для визуализации -->
        </visual>
        <collision>
            <geometry>
                <sphere radius="0.066"/> <!-- Геометрия для столкновений -->
            </geometry>
        </collision>
        <inertial>
            <origin xyz="0 0 0" rpy="0 0 0"/> <!-- Центр масс колеса -->
            <mass value="0.05" /> <!-- Масса колеса -->
            <inertia ixx="0.000042" ixy="0.0" ixz="0.0"
                     iyy="0.000042" iyz="0.0"
                     izz="0.000227" /> <!-- Моменты инерции -->
        </inertial>
    </link>

    <!-- Настройки для визуализации заднего правого колеса в Gazebo -->
    <gazebo reference="back_right_wheel">
        <material>Gazebo/Black</material>
    </gazebo>

</robot>
